{"uuid": "9c4c6e63-05c2-4d08-90c5-6f7b03ca6fc2", "children": ["d099422b-f27a-4a71-a636-735a073aca73"], "befores": [{"name": "req", "status": "broken", "statusDetails": {"message": "TypeError: not all arguments converted during string formatting\n", "trace": "  File \"D:\\pythonProject\\EasyTest\\venv\\lib\\site-packages\\pluggy\\_callers.py\", line 39, in _multicall\n    res = hook_impl.function(*args)\n  File \"D:\\pythonProject\\EasyTest\\venv\\lib\\site-packages\\_pytest\\fixtures.py\", line 1111, in pytest_fixture_setup\n    result = call_fixture_func(fixturefunc, request, kwargs)\n  File \"D:\\pythonProject\\EasyTest\\venv\\lib\\site-packages\\_pytest\\fixtures.py\", line 890, in call_fixture_func\n    fixture_result = fixturefunc(**kwargs)\n  File \"D:\\pythonProject\\EasyTest\\test_interface\\conftest.py\", line 33, in req\n    params = utils.generate_data_from_excel(file_name)\n  File \"D:\\pythonProject\\EasyTest\\test_interface\\utils\\__init__.py\", line 17, in generate_data_from_excel\n    logger.info('============path:',str(path))\n  File \"C:\\Users\\xiaomai\\AppData\\Local\\Programs\\Python\\Python38\\lib\\logging\\__init__.py\", line 1442, in info\n    self._log(INFO, msg, args, **kwargs)\n  File \"C:\\Users\\xiaomai\\AppData\\Local\\Programs\\Python\\Python38\\lib\\logging\\__init__.py\", line 1585, in _log\n    self.handle(record)\n  File \"C:\\Users\\xiaomai\\AppData\\Local\\Programs\\Python\\Python38\\lib\\logging\\__init__.py\", line 1595, in handle\n    self.callHandlers(record)\n  File \"C:\\Users\\xiaomai\\AppData\\Local\\Programs\\Python\\Python38\\lib\\logging\\__init__.py\", line 1657, in callHandlers\n    hdlr.handle(record)\n  File \"C:\\Users\\xiaomai\\AppData\\Local\\Programs\\Python\\Python38\\lib\\logging\\__init__.py\", line 950, in handle\n    self.emit(record)\n  File \"D:\\pythonProject\\EasyTest\\venv\\lib\\site-packages\\_pytest\\logging.py\", line 342, in emit\n    super().emit(record)\n  File \"C:\\Users\\xiaomai\\AppData\\Local\\Programs\\Python\\Python38\\lib\\logging\\__init__.py\", line 1089, in emit\n    self.handleError(record)\n  File \"C:\\Users\\xiaomai\\AppData\\Local\\Programs\\Python\\Python38\\lib\\logging\\__init__.py\", line 1081, in emit\n    msg = self.format(record)\n  File \"C:\\Users\\xiaomai\\AppData\\Local\\Programs\\Python\\Python38\\lib\\logging\\__init__.py\", line 925, in format\n    return fmt.format(record)\n  File \"D:\\pythonProject\\EasyTest\\venv\\lib\\site-packages\\_pytest\\logging.py\", line 113, in format\n    return super().format(record)\n  File \"C:\\Users\\xiaomai\\AppData\\Local\\Programs\\Python\\Python38\\lib\\logging\\__init__.py\", line 664, in format\n    record.message = record.getMessage()\n  File \"C:\\Users\\xiaomai\\AppData\\Local\\Programs\\Python\\Python38\\lib\\logging\\__init__.py\", line 369, in getMessage\n    msg = msg % self.args\n"}, "start": 1663054702225, "stop": 1663054707678}], "start": 1663054702225, "stop": 1663054708198}